# 你不知道的前端异常处理

除了调试，处理异常或许是程序员编程时间占比最高的了。我们天天和各种异常打交道，就好像我们天天和 bug 打交道一样。因此正确认识异常，并作出合适的异常处理就显得很重要了。

我们先尝试抛开前端这个限定条件，来看下更广泛意义上程序的报错以及异常处理。不管是什么语言，都会有异常发生。而我们程序员要做的就是正确识别程序中的各种异常，并针对其做相应的「**异常处理**」。

然而，很多人对异常的处理方式是「**事后修补**」，即某个异常发生的时候，增加对应的条件判断，这真是一种非常低效的开发方式，非常不推荐大家这么做。那么究竟如何正确处理异常呢？由于不同语言有不同的特性，因此异常处理方式也不尽相同。但是异常处理的思维框架一定是一致的。本文就「前端」一场进行详细阐述，但是读者也可以稍加修改延伸到其他各个领域。

>   本文讨论的异常指的是软件异常，而非硬件异常。

## 什么是异常

用直白的话来解释异常就是「**程序发生了意想不到的情况，这种情况影响到了程序的正确运行**」。

从根本上来说，异常就是一个「**数据结构**」，其保存了一场发生的相关信息，比如错误码，错误信息等。以 JS 中的标准内置对象 Error 为例，其标准属性有 name 和 message。然而不同的浏览器厂商有自己的自定义属性，这些属性并不通用。比如 Mozilla 浏览器就增加了 filename 和 stack 等属性。

值得注意的是错误只有被抛出，才会产生异常，不被抛出的错误不会产生异常。比如：

```js
function t() {
  console.log("start");
  new Error();
  console.log("end");
}
t();
```

![img](https://mmbiz.qpic.cn/mmbiz_gif/CuarlDcuWP43cUG1rt71pmzwOSkrtsfhic1n8kUQnIA0zxSE5saOS1PFDvcZVFXo2I3PLiaibgoXHh5mVgawZKlnw/640?wx_fmt=gif&tp=webp&wxfrom=5&wx_lazy=1)

这段代码不会产生任何的异常，控制台也不会有任何错误输出。

## 异常的分类

按照产生异常时程序是否正在运行，我们可以将错误分为「**编译时异常**」和「**运行时异常**」。

编译时异常指的是源代码在编译成可执行代码之前产生的异常。而运行时异常指的是可执行代码被装载到内存中执行之后产生的异常。

### 编译时异常

我们知道 TS 最终会被编译成 JS，从而在 JS Runtime 中执行。既然存在编译，就有可能编译失败，就会有编译时异常。

比如我使用 TS 写出了如下代码：

```typescript
const s: string = 123
```

这很明显是错误的代码，我给 s 声明了 string 类型，但是却给它赋值 number。

当我们使用 tsc 尝试编译这个文件时就会有异常抛出：

```shell
tsc a.ts
a.ts:1:7 - error TS2322: Type '123' is not assignable to type 'string'.

1 const s: string = 123;
        ~


Found 1 error.
```

这个异常就是编译时异常，因为我的代码还没执行。

然而并不是你用了 TS 才存在编译时异常，JS 同样有编译异常。有的人可能会问 JS 不是解释性语言么？是边解释变执行，没有编译环节，怎么会有编译时异常？

别急，我举个例子你就明白了，如下代码：

```js
function t() {
  console.log('start')
  await sa
  console.log('end')
}
t()
```

上面的代码由于存在语法错误，不会编译通过，因此并不会打印 start，侧面证明了这是一个编译时异常。尽管 JS 是解释语言，也依然存在编译阶段，这是必然的，因此自然也会有编译异常。

总体来说，编译异常可以在代码被编译成最终代码前被发现，因此对我们的伤害更小。接下来，看一下令人心生畏惧的「**运行时异常**」。

### 运行时异常

相信大家对运行时异常非常熟悉。这恐怕是广大前端碰到最多的异常类型了。众所周知的 NPE（Null Pointer Exception）就是运行时异常。

将上面的例子稍加改造，得到下面代码：

```js
function t() {
  console.log("start");
  throw 1;
  console.log("end");
}
t();
```

![img](https://mmbiz.qpic.cn/mmbiz_gif/CuarlDcuWP43cUG1rt71pmzwOSkrtsfhkz5OBT435cheAKM6AfVsAO7H9icBthnlxPS7OGe9VT1DvIvs4KBkRBw/640?wx_fmt=gif&tp=webp&wxfrom=5&wx_lazy=1)

>   注意 end 没有打印，并且 t 没有弹出栈。实际上 t 最终还是会被弹出的，只不过和普通的返回不一样。

如上，则会打印出 start。由于异常是在代码运行过程中抛出的，因此这个异常属于运行时异常。相对于编译时异常，这种异常更加难以发现。上面的例子可能比较简单，但是如果我的异常是隐藏在某一个流程控制语句里面呢？程序就可能在客户的电脑走入哪个跑出异常的特殊语句中，而你的电脑走入了正常语句。这就是著名的「《在我电脑上好好的》」事件。

## 异常的传播

异常的传播和浏览器事件模型有很大的相似性，只不过那个是作用在「DOM 这样的数据结构」，这个则是作用在「函数调用栈这种数据结构」，并且事件传播存在捕获阶段，异常传播是没有的。不同 C 语言，JS 中异常传播是自动的，不需要程序员手动地一层层传递，如果一个异常没有被 catch，它会沿着函数调用栈一层层传播直到栈空。

异常处理中有两个关键词，它们是「**throw（抛出异常）**」和「**catch（处理异常）**」。当一个异常被抛出的时候，异常的传播就开始了。异常会不断传播直到遇到第一个 catch。如果程序员没有手动 catch，那么一般而言程序会抛出类似「**unCaughtError**」，表示发生了一个异常，并且这个异常没有被程序中的任何 catch 语言处理。未被捕获的异常通常会被打印在控制台上， 里面有详细的堆栈信息，从而帮助程序员快速排查问题。实际上我们的程序目标是「**避免 unCaughtError**」这种异常，而不是一般性异常。

### 一点小前提

由于 JS 的 Error 对象没有 code 属性，只能根据 message 来呈现，不是很方便。我们可以尝试做简单扩展。

```js
var oldError = Error
Error = function({ code, message, fileName, lineNumber }) {
	var error = new oldError(message, fileName, lineNumber)
  error.code = code
  return error
}
```

### 手动抛出 or 自动抛出

异常既然可以有程序员自己手动抛出，也可以有程序自动抛出。

```js
throw new Error("I'm Eception.")
```

（手动抛出的例子）

```js
var a = null
a.toString() // Thrown: TypeError: Cannot read property 'toString' of null
```

（程序自动抛出的例子）

自动抛出异常很好理解，毕竟我们哪个程序员没有看到过程序自动抛出的异常呢？

>   "这个异常突然就跳出来！吓我一跳！"，某个不知名程序员说到。

那什么时候应该手动抛出异常呢？

一个指导原则就是「**你已经预知到程序不能正确进行下去了**」。比如我们要实现除法，首先我们要考虑的是除数为 0 的情况。当除数为 0 的时候我们应该怎么办呢？是抛出异常，还是 return 一个特殊值？答案是都可以，你自己能区分就行，这里没有一个严格的标准，我们先来看下抛出异常，告诉调用者「你的输入，我处理不了」这种情况。

```js
function divide(a, b) {
  a = +a;
  b = +b; // 转化成数字
  if (!b) {
    // 匹配 +0, -0, NaN
    throw new Error({
      code: 1,
      message: "Invalid dividend " + b,
    });
  }
  if (Number.isNaN(a)) {
    // 匹配 NaN
    throw new Error({
      code: 2,
      message: "Invalid divisor " + a,
    });
  }
  return a / b;
}
```

上面代码会在两种情况下抛出异常，告诉调用者你的输入我处理不了。由于这两个异常都是程序员自动手动抛出的，因此是**「可预知的异常」**。

刚才说了，我们也可以通过返回值来区分异常输入。我们来看下返回值输入是什么，以及和异常有什么关系。

### 异常 or 返回

如果是基于异常形式（遇到不能处理的输入就抛出异常）。当别的代码调用 divide 的时候，需要自己 catch。

```js
function t() {
  try {
    divide("foo", "bar");
  } catch (err) {
    if (err.code === 1) {
      return console.log("被除数必须是除0之外的数");
    }
    if (err.code === 2) {
      return console.log("除数必须是数字");
    }
    throw new Error("不可预知的错误");
  }
}
```

然而就像我们上面说的，divide 函数设计的时候，也完全可以不用异常，而是使用返回值来区分。

```js
function divide(a, b) {
  a = +a;
  b = +b; // 转化成数字
  if (!b) {
    // 匹配 +0, -0, NaN
    return new Error({
      code: 1,
      message: "Invalid dividend " + b,
    });
  }
  if (Number.isNaN(a)) {
    // 匹配 NaN
    return new Error({
      code: 2,
      message: "Invalid divisor " + a,
    });
  }
  return a / b;
}
```

 当然，我们使用方式也要做出相应改变。

```js

function t() {
  const res = divide("foo", "bar");

  if (res.code === 1) {
    return console.log("被除数必须是除0之外的数");
  }
  if (res.code === 2) {
    return console.log("除数必须是数字");
  }
  return new Error("不可预知的错误");
}
```

这种函数设计和抛出异常的设计方式从功能上是一样的，只是告诉调用方的方式不同。如果你选择第二种，而不是抛出异常，那么实际上需要调用方书写额外的代码，用来区分正常情况和异常情况，这并不是一种良好的变成习惯。

然而在 Go 等返回值可以为复数的语言中，我们无需使用上面蹩脚的方式，而是可以：

```go
res, err := divide("foo", "bar");
if err != nil {
    log.Fatal(err)
}
```

这是和 Java 和 JS 等语言使用 try catch 不一样的地方，Go 是通过 panic recover defer 机制来进行异常处理的。感兴趣的可以去看看 Go 源码关于错误测试部分。

可能大家对 Go 不太熟悉。没关系，我们继续看下 shell。实际上 shell 也是通过返回值来处理异常，我们可以通过 `$?` 拿到上一个命令的返回值，这本质上也是一种调用栈的传播行为，而是通过返回值而不是捕获来处理异常。

>   作为函数返回值处理和 try catch 一样，这是语言的设计者和开发者共同决定的一件事情。

上面提到了异常传播是作用在「函数调用栈」上的。当一个异常发生时，岂会沿着函数调用栈逐层返回，直到第一个 catch 语句。当然 catch 内部仍然可能触发异常（自动或手动）。如果 catch 语句内部发生了异常，也一样会沿着其函数调用栈继续执行上述逻辑，专业术语是「**stack unwinding**」。

>   实际上并不是所有的语言都会进行 stack unwinding，这个我们会在接下来的《运行时异常可以恢复么？》部分讲解。

![](https://raw.githubusercontent.com/LaamGinghong/pics/master/img/20201102102638.png)



伪代码来描述一下：

```js
function bubble(error, fn) {
  if (fn.hasCatchBlock()) {
    runCatchCode(error);
  }
  if (callstack.isNotEmpty()) {
    bubble(error, callstack.pop());
  }
}
```

>   从我的伪代码可以看出所谓的 stack unwinding 其实就是 callstack.pop()

这就是异常传播的一切！仅此而已

## 异常的处理

我们已经了解到异常的传播方式。那么接下来的问题是，我们应该如何在这个传播过程中处理异常呢？

我们来看一个简单的例子：

```js
function a() {
  b();
}
function b() {
  c();
}
function c() {
  throw new Error("an error  occured");
}
a();
```

我们将上面的代码放到 chrome 中执行，会在控制台显示如下输出：

![](https://raw.githubusercontent.com/LaamGinghong/pics/master/img/20201102103024.png)

我们可以清楚地看到函数的调用关系。即错误发生在 c 中发生的，而 c 是 b 调用的，b 是 a 调用的。这个函数调用栈是为了方便开发者定位问题而存在的。

上面的代码，我们并没有 catch 错误，因此上面才会有「uncaught Error」。

那么如果我们 catch 会发生什么变化呢？catch 会对结果产生什么样的影响？在 a、b、c 中 catch 的效果是一样的吗？

我们分别看下：

```js
function a() {
  b();
}
function b() {
  c();
}
function c() {
  try {
    throw new Error("an error  occured");
  } catch (err) {
    console.log(err);
  }
}
a();
```

（在 c 中 catch）

我们将上面的代码放到 chrome 中执行，会在控制台显示如下输出：

![](https://raw.githubusercontent.com/LaamGinghong/pics/master/img/20201102103404.png)

可以看到，此时已经没有「uncaught Error」了，仅仅在控制台显示了标准输出，而非错误输出。然而更重要的是，如果我们没有 catch，后面的同步代码将不会继续执行。

比如在 c 的 throw 下面增加一行代码，这行代码是无法被执行的，**无论这个错误有没有被捕获。**

```js
function c() {
  try {
    throw new Error("an error  occured");
    console.log("will never run");
  } catch (err) {
    console.log(err);
  }
}
```

我们将 catch 移动到 b 中试试看。

```js
function a() {
  b();
}
function b() {
  try {
    c();
  } catch (err) {
    console.log(err);
  }
}
function c() {
  throw new Error("an error  occured");
}

a();
```

（在 b 中 catch）

在这个例子中，和上面在 c 中捕获没有什么本质不同，其实放到 a 中捕获也是一样，这里不再贴代码了，感兴趣的自己试下。

既然处于函数调用栈顶部的函数报错，其函数调用栈下方的任意代码都可以进行捕获，并且效果没有本质不同，那么问题来了，我们到底应该在哪里进行错误处理呢？

答案是责任链模式。我们先来简单介绍一下责任链模式。

假如 lucifer 要请假：

*   如果请假天数小于等于 1 天，则主管同意即可；
*   如果请假天数大于 1 天，但是小于等于 3 天，则需要 CTO 同意；
*   如果请假天数大于 3 天，则需要老板同意。

![](https://raw.githubusercontent.com/LaamGinghong/pics/master/img/20201102104034.png)

这就是一个典型的责任链模式。谁有责任干什么事情是确定的，不要做自己能力范围之外的事情。比如主管不要去同意大于一天的审核。

举个例子，假设我们的应用有三个异常处理类，它们分别是：用户输入错误、网络错误和类型错误。如下代码，当代码执行的时候会报错一个用户输入异常。这个异常没有被 C 捕获，会 unwind stack 到 b，而 b 中 catch 到这个错误之后，通过查看 code 值判断其可以被处理，于是打印 `I can handle this`。

```js
function a() {
  try {
    b();
  } catch (err) {
    if (err.code === "NETWORK_ERROR") {
      return console.log("I can handle this");
    }
    // can't handle, pass it down
    throw err;
  }
}
function b() {
  try {
    c();
  } catch (err) {
    if (err.code === "INPUT_ERROR") {
      return console.log("I can handle this");
    }
    // can't handle, pass it down
    throw err;
  }
}
function c() {
  throw new Error({
    code: "INPUT_ERROR",
    message: "an error  occured",
  });
}

a();
```

而如果 c 中抛出识别的异常，比如网络异常，那么 b 是无法处理的，虽然 b catch 住了，但是由于你无法处理，因此一个好的做法是继续抛出异常，而不是 **吞没** 异常。不要畏惧错误，抛出它。**只有没被捕获的异常才是可怕的** ，如果一个错误可以被捕获并得到正确处理，它就不可怕。

举个例子：

```js
function a() {
  try {
    b();
  } catch (err) {
    if (err.code === "NETWORK_ERROR") {
      return console.log("I can handle this");
    }
    // can't handle, pass it down
    throw err;
  }
}
function b() {
  try {
    c();
  } catch (err) {
    if (err.code === "INPUT_ERROR") {
      return console.log("I can handle this");
    }
  }
}
function c() {
  throw new Error({
    code: "NETWORK_ERROR",
    message: "an error  occured",
  });
}

a();
```

如上代码不会有任何异常被抛出，它被完全吞没了，这对我们调试问题简直是灾难。因此切记「不要吞没你不能处理的异常」。正确的做法应该是上面讲的「只捕获你可以处理的异常，将你不能处理的异常抛出来」，这就是责任链模式的典型应用。

这只是一个简单的例子，就足以绕半天。实际业务肯定比这个复杂多得多。因此异常处理绝对不是一件容易的事。

如果说谁来处理是一件困难的事情，那么在异步中决定谁来处理异常就是难上加难，我们来看下。

## 同步与异步

同步异步一直是前端难以跨域的坎，对于异常处理也是一样。以 NodeJS 中用的比较多的「读取文件」API 为例。它有两个版本，一个是异步，一个是同步。同步读取仅仅应该被用在没了这个文件无法进行下去的时候，比如读取一个配置文件，而不应该再比如浏览器中读取用户磁盘上的一张图片等，这样会造成主线程阻塞，导致浏览器卡死。

```js
// 异步读取文件
fs.readFileSync();
// 同步读取文件
fs.readFile();
```

当我们试图**「同步」**读取一个不存在的文件的时候，会抛出以下异常：

```js
fs.readFileSync('something-not-exist.lucifer');
console.log('脑洞前端');
Thrown:
Error: ENOENT: no such file or directory, open 'something-not-exist.lucifer'
    at Object.openSync (fs.js:446:3)
    at Object.readFileSync (fs.js:348:35) {
  errno: -2,
  syscall: 'open',
  code: 'ENOENT',
  path: 'something-not-exist.lucifer'
}
```

并且脑洞前端是不会被打印出来的，这个比较好理解，我们上面已经解释过了。

而如果以异步的方式：

```js
fs.readFile('something-not-exist.lucifer', (err, data) => {if(err) {throw err}});
console.log('lucifer')
lucifer
undefined
Thrown:
[Error: ENOENT: no such file or directory, open 'something-not-exist.lucifer'] {
  errno: -2,
  code: 'ENOENT',
  syscall: 'open',
  path: 'something-not-exist.lucifer'
}
```

脑洞前端是会被打印出来的。

其本质在于 `fs.readFile` 已经调用成功，并从函数调用栈返回并执行到下一行打印语句。因此错误发生的时候，调用栈是空的，这一点可以从上面的错误堆栈信息中看出来。

而 try catch 的作用仅仅是捕获当前调用栈的错误，因此异步的错误是无法捕获的，比如：

```js
try {
  fs.readFile("something-not-exist.lucifer", (err, data) => {
    if (err) {
      throw err;
    }
  });
} catch (err) {
  console.log("catching an error");
}
```

上面的 `catching an error` 不会被打印，因为错误抛出的时候，调用栈中不包含这个 catch 语句，而仅仅在执行 `fs.readFile` 的时候才会。

如果我们换成同步读取文件：

```js
try {
  fs.readFileSync("something-not-exist.lucifer");
} catch (err) {
  console.log("catching an error");
}
```

上面的代码会打印 `catching an error`，因为读取文件被同步发起，文件返回之前线程会被挂起，当线程恢复执行的时候，`fs.readFileSync` 仍然在函数调用栈中，因此 `fs.readFileSync` 产生的异常会冒泡到 catch 语句中。

简单来说，「**异步产生的错误不能用 try catch 捕获，而要使用回调捕获**」。

如果你非要用 try catch 来捕获，则可以使用 async await 来包装异步语句，将异步语法转换成同步语法的形式，但这个异步语句必须是一个 Promise 类型才能使用 async await 包装。

```js
rejectIn = (ms) =>
  new Promise((_, r) => {
    setTimeout(() => {
      r(1);
    }, ms);
  });
async function t() {
  try {
    await rejectIn(0);
  } catch (err) {
    console.log("catching an error", err);
  }
}

t();
```

而如果我们使用 babel 转义下，会发现 try catch 不见了，变成了 switch case语句。这就是 try catch 可以捕获异常异常的原因，仅此而已。

![](https://raw.githubusercontent.com/LaamGinghong/pics/master/img/20201102114828.png)

（babel 转义结果）

>   虽然浏览器并不像 babel 转义这般实现，但是至少我们明白了一点，目前的 try catch 的作用机制是无法捕获异步异常的。

异步的错误处理推荐使用容器包装，比如 Promise。然后使用 catch 进行处理。实际上 Promise 的 catch 和 try catch 的 catch 有很多相似的地方，大家可以类比过去。

和同步处理一样，很多原则都是通用的。比如异步也不要去吞没异常。下面的代码是不好的，因为它吞没了**「它不能处理的」**异常。

```js
var p = Promise.reject(1)
p.catch(() => {})
```

更合适的做法应该类似这种：

```js
var p = Promise.reject(1)
p.catch(err => {
  if(err === 1) {
    return console.log('I can handle this')
  }
  throw err
})
```

## 彻底消除运行时异常可能么？

我个人对目前前端现状最为头疼的一点是：「**大家过分依赖运行时，而严重忽略编译时**」。我见过很多程序，如果不运行，根本不知道程序是怎么走的，每个变量的 shape 是什么，怪不得处处都可以看到打印语句。我相信你一定对此感同身受。也许你是写出这种代码的人，也许你是帮别人擦屁股的人。为什么会这样？就是因为大家过分依赖运行时。TS 的出现很大程度上改变了这一点，前提是你用的是 TypeScript 而不是 AnyScript。其实 eslint 以及 stylint 对此也有贡献，毕竟他们是静态分析工具。

我强烈建议将异常保留在编译时，而不是运行时。不妨极端一点来看：加入所有的异常都在编译时发生，而一定不会在运行时发生。那么我们是不是就可以「信心满满」地对应用进行重构？

幸运的事，我们能够做到。只不过如果当前语言做不到的话，则需要对现有的语言体系进行改造。这种改造成本真的很大，不仅仅是 API，编程模型也发生了翻天覆地的变化，不然函数时也不会这么多年都没有得到普及。

## 运行时异常可以恢复吗？

最后要讨论的一个主题是运行时异常是否可以恢复。先来解释一下，什么是运行时异常的恢复。还是用上面的例子：

```js
function t() {
  console.log("start");
  throw 1;
  console.log("end");
}
t();
```

我们知道无论如何都无法打印 end，即使你 catch 了也无济于事。

如果我想让它可以打印呢？我想让程序面对异常可以自己 recover 怎么办？我已经捕获这个错误，并且我确信我可以处理，让流程继续走下去，如果有能力做到这个，这个就是「**运行时异常恢复**」。

遗憾地告诉你，目前没有任何一个引擎可以做到这一点。

## 最佳实践

通过前面的学习，你已经知道了异常是什么，异常是怎么产生的，以及如何正确处理异常（同步和异步）。接下来，我们谈一下异常处理的最佳实践。

我们平时开发一个应用。如果站在生产者和消费者的角度来看的话。当我们使用别人封装的框架，库，模块，甚至是函数的时候，我们就是消费者。而当我们写的东西被他人使用的时候，我们就是生产者。

实际上，就算是生产者内部也会有多个模块构成，多个模块之间也会有生产者和消费者的再次身份转化。不过为了简单起见，本文不考虑这种关系。这里的生产者指的就是给他人使用的功能，是纯粹的生产者。

从这个角度出发，来看下异常处理的最佳实践。

### 作为消费者

当作为消费者的时候，我们关心的是使用的功能是否会抛出异常，如果是，它们有哪些异常，比如：

```js
import foo from "lucifer"

try {
  foo.bar()
} catch (err) {
  // 有哪些异常？
}
```

当然，理论上 `foo.bar` 有可能产生任何异常，而不管它的 API 是这么写的。但是我们关心的是「可预期的异常」。因此你一定希望这个时候有一个 API 文档，详细列举了这个 API 可能产生的异常有哪些。

比如 `foo.bar` 有 4 种异常，分别是 A、B、C、D，其中 A 和 B 是我可以处理的，而 C 和 D 我不能处理，那我应该：

```js
import foo from "lucifer"

try {
  foo.bar()
} catch (err) {
	if(err.code === 'A') return console.log('A happen')
  else if(err.code === 'B') return console.log('B happen')
  throw err
}
```

可以看出，不管是 C 和 D，还是 API 中没有列举的各种可能异常，我们的做法都是直接抛出。

![](https://raw.githubusercontent.com/LaamGinghong/pics/master/img/20201102143052.png)

### 作为生产者

如果你作为生产者，你要做的就是提供上面提到的详细的 API，告诉消费者你的可能错误有哪些。这样消费者就可以在 catch 中进行相应判断，处理异常情况。

![](https://raw.githubusercontent.com/LaamGinghong/pics/master/img/20201102143132.png)

你可以提供类似上图的错误表，让大家可以很快知道可能存在的**「可预知」**异常有哪些。不得不吐槽一句，在这一方面很多框架，库做的都很差。希望大家可以重视起来，努力维护良好的前端开发大环境。

